Workbook
Name IYD7460_: 'jan_26 (2)'!$D$2:$D$4
Name Placa: Planilha2!#REF!
Name placas: Planilha2!#REF!

Sheet Planilha2
A1: IUG8882 | B1: Wesley
A2: RKV1173 | B2: William
A3: LTY8B39 | B3: Gilberto
A4: IUG8855 | B4: Rosinaldo
A5: RJA2C91 | B5: Edilson
A6: IUG8744 | B6: Sandro
A7: IUG8767 | B7: Jerson
A8: IYD7460 | B8: Paulo
A9: IXY4731 | B9: Osvaldo
A10: IVX5G13 | B10: Heremilton
A11: TBO7E32 | B11: Manoel
A12: TRD2G21 | B12: Arnaldo

Sheet Terceiros
A1: Data | B1: Placa | C1: Carreta | D1: Motorista | E1: Valor Frete | F1: Valor Mercadoria | G1: Peso | H1: % Frete | I1: Hr Saida | J1: Hr Chegada | K1: Tempo | L1: Frete | M1: % Frete T | N1: Vols | O1: Qtde Entregas | P1: Entregas Realizadas | Q1: Retornadas | R1: % Entrega | S1: Meta | T1: Cidade Destino | U1: Nfs Voltaram | V1: Código ocorrência
A2: 46027 | B2: NXW6G67 | D2: Marinaldo | E2: 4275.3 | F2: 77009.21 | G2: 1483 | H2: =Tabela35[[#This Row],[Valor Frete]]/Tabela35[[#This Row],[Valor Mercadoria]] -> 0.055516736 | K2: =Tabela35[[#This Row],[Hr Chegada]]-Tabela35[[#This Row],[Hr Saida]] -> 0 | L2: 500 | M2: =Tabela35[[#This Row],[Frete]]/Tabela35[[#This Row],[Valor Frete]] -> 0.11695086 | N2: 45 | O2: 4 | P2: 4 | Q2: =Tabela35[[#This Row],[Qtde Entregas]]-Tabela35[[#This Row],[Entregas Realizadas]] -> 0 | R2: =Tabela35[[#This Row],[Entregas Realizadas]]/Tabela35[[#This Row],[Qtde Entregas]] -> 1 | S2: =IF(Tabela35[[#This Row],[% Entrega]]>=96%,"Atendeu a Meta","Não Atendeu a Meta") -> Atendeu a Meta | T2: Belém | U2: 0 | V2: 0
A3: 46238 | B3: NSE5B85 | D3: Silvio | E3: 7461.93 | F3: 46748.29 | G3: 457 | H3: =Tabela35[[#This Row],[Valor Frete]]/Tabela35[[#This Row],[Valor Mercadoria]] -> 0.15961931 | K3: =Tabela35[[#This Row],[Hr Chegada]]-Tabela35[[#This Row],[Hr Saida]] -> 0 | M3: =Tabela35[[#This Row],[Frete]]/Tabela35[[#This Row],[Valor Frete]] -> 0 | Q3: =Tabela35[[#This Row],[Qtde Entregas]]-Tabela35[[#This Row],[Entregas Realizadas]] -> 0 | R3: =Tabela35[[#This Row],[Entregas Realizadas]]/Tabela35[[#This Row],[Qtde Entregas]] -> #DIV/0! | S3: =IF(Tabela35[[#This Row],[% Entrega]]>=96%,"Atendeu a Meta","Não Atendeu a Meta") -> #DIV/0!
A4: 46241 | B4: NXW6G67 | D4: Marinaldo | E4: 4770.58 | F4: 89040.79 | G4: 1291 | H4: =Tabela35[[#This Row],[Valor Frete]]/Tabela35[[#This Row],[Valor Mercadoria]] -> 0.053577467 | K4: =Tabela35[[#This Row],[Hr Chegada]]-Tabela35[[#This Row],[Hr Saida]] -> 0 | L4: 500 | M4: =Tabela35[[#This Row],[Frete]]/Tabela35[[#This Row],[Valor Frete]] -> 0.10480906 | N4: 208 | O4: 8 | P4: 6 | Q4: =Tabela35[[#This Row],[Qtde Entregas]]-Tabela35[[#This Row],[Entregas Realizadas]] -> 2 | R4: =Tabela35[[#This Row],[Entregas Realizadas]]/Tabela35[[#This Row],[Qtde Entregas]] -> 0.75 | S4: =IF(Tabela35[[#This Row],[% Entrega]]>=96%,"Atendeu a Meta","Não Atendeu a Meta") -> Não Atendeu a Meta | T4: Belém | U4: 2 | V4: 0
A5: 46245 | B5: NXW6G67 | D5: Marinaldo | E5: 7701.21 | F5: 160981.76 | G5: 1938 | H5: =Tabela35[[#This Row],[Valor Frete]]/Tabela35[[#This Row],[Valor Mercadoria]] -> 0.047839022 | K5: =Tabela35[[#This Row],[Hr Chegada]]-Tabela35[[#This Row],[Hr Saida]] -> 0 | L5: 500 | M5: =Tabela35[[#This Row],[Frete]]/Tabela35[[#This Row],[Valor Frete]] -> 0.064924862 | N5: 346 | O5: 14 | P5: 14 | Q5: =Tabela35[[#This Row],[Qtde Entregas]]-Tabela35[[#This Row],[Entregas Realizadas]] -> 0 | R5: =Tabela35[[#This Row],[Entregas Realizadas]]/Tabela35[[#This Row],[Qtde Entregas]] -> 1 | S5: =IF(Tabela35[[#This Row],[% Entrega]]>=96%,"Atendeu a Meta","Não Atendeu a Meta") -> Atendeu a Meta | T5: Ananindeua
A6: 46247 | B6: NXW6G67 | D6: Marinaldo | E6: 5668.48 | F6: 94110.1 | G6: 787 | H6: =Tabela35[[#This Row],[Valor Frete]]/Tabela35[[#This Row],[Valor Mercadoria]] -> 0.06023243 | K6: =Tabela35[[#This Row],[Hr Chegada]]-Tabela35[[#This Row],[Hr Saida]] -> 0 | L6: 500 | M6: =Tabela35[[#This Row],[Frete]]/Tabela35[[#This Row],[Valor Frete]] -> 0.088207068 | N6: 201 | O6: 20 | P6: 19 | Q6: =Tabela35[[#This Row],[Qtde Entregas]]-Tabela35[[#This Row],[Entregas Realizadas]] -> 1 | R6: =Tabela35[[#This Row],[Entregas Realizadas]]/Tabela35[[#This Row],[Qtde Entregas]] -> 0.95 | S6: =IF(Tabela35[[#This Row],[% Entrega]]>=96%,"Atendeu a Meta","Não Atendeu a Meta") -> Não Atendeu a Meta | T6: Belém | U6: 1 | V6: 10
A7: 46252 | B7: NXW6G67 | D7: Marinaldo | E7: 8639.84 | F7: 131603.82 | G7: 1536 | H7: =Tabela35[[#This Row],[Valor Frete]]/Tabela35[[#This Row],[Valor Mercadoria]] -> 0.065650374 | K7: =Tabela35[[#This Row],[Hr Chegada]]-Tabela35[[#This Row],[Hr Saida]] -> 0 | L7: 500 | M7: =Tabela35[[#This Row],[Frete]]/Tabela35[[#This Row],[Valor Frete]] -> 0.057871442 | N7: 194 | O7: 31 | P7: 31 | Q7: =Tabela35[[#This Row],[Qtde Entregas]]-Tabela35[[#This Row],[Entregas Realizadas]] -> 0 | R7: =Tabela35[[#This Row],[Entregas Realizadas]]/Tabela35[[#This Row],[Qtde Entregas]] -> 1 | S7: =IF(Tabela35[[#This Row],[% Entrega]]>=96%,"Atendeu a Meta","Não Atendeu a Meta") -> Atendeu a Meta | T7: Ananindeua | U7: 1 | V7: 9
A8: 46253 | B8: JVY9G53 | D8: Pedro | E8: 8971 | F8: 79084.99 | G8: 808 | H8: =Tabela35[[#This Row],[Valor Frete]]/Tabela35[[#This Row],[Valor Mercadoria]] -> 0.11343493 | K8: =Tabela35[[#This Row],[Hr Chegada]]-Tabela35[[#This Row],[Hr Saida]] -> 0 | L8: 500 | M8: =Tabela35[[#This Row],[Frete]]/Tabela35[[#This Row],[Valor Frete]] -> 0.055735147 | N8: 165 | O8: 14 | P8: 14 | Q8: =Tabela35[[#This Row],[Qtde Entregas]]-Tabela35[[#This Row],[Entregas Realizadas]] -> 0 | R8: =Tabela35[[#This Row],[Entregas Realizadas]]/Tabela35[[#This Row],[Qtde Entregas]] -> 1 | S8: =IF(Tabela35[[#This Row],[% Entrega]]>=96%,"Atendeu a Meta","Não Atendeu a Meta") -> Atendeu a Meta
A9: 46268 | B9: NSE5B85 | D9: Marinaldo | E9: 5954.82 | F9: 69924.04 | G9: 1514 | H9: =Tabela35[[#This Row],[Valor Frete]]/Tabela35[[#This Row],[Valor Mercadoria]] -> 0.085161269 | K9: =Tabela35[[#This Row],[Hr Chegada]]-Tabela35[[#This Row],[Hr Saida]] -> 0 | L9: 500 | M9: =Tabela35[[#This Row],[Frete]]/Tabela35[[#This Row],[Valor Frete]] -> 0.083965594 | Q9: =Tabela35[[#This Row],[Qtde Entregas]]-Tabela35[[#This Row],[Entregas Realizadas]] -> 0 | R9: =Tabela35[[#This Row],[Entregas Realizadas]]/Tabela35[[#This Row],[Qtde Entregas]] -> #DIV/0! | S9: =IF(Tabela35[[#This Row],[% Entrega]]>=96%,"Atendeu a Meta","Não Atendeu a Meta") -> #DIV/0!
A10: 46269 | B10: NSE5B85 | D10: Marinaldo | E10: 24238.02 | F10: 167202.07 | G10: 2185 | H10: =Tabela35[[#This Row],[Valor Frete]]/Tabela35[[#This Row],[Valor Mercadoria]] -> 0.14496244 | K10: =Tabela35[[#This Row],[Hr Chegada]]-Tabela35[[#This Row],[Hr Saida]] -> 0 | L10: 500 | M10: =Tabela35[[#This Row],[Frete]]/Tabela35[[#This Row],[Valor Frete]] -> 0.020628748 | Q10: =Tabela35[[#This Row],[Qtde Entregas]]-Tabela35[[#This Row],[Entregas Realizadas]] -> 0 | R10: =Tabela35[[#This Row],[Entregas Realizadas]]/Tabela35[[#This Row],[Qtde Entregas]] -> #DIV/0! | S10: =IF(Tabela35[[#This Row],[% Entrega]]>=96%,"Atendeu a Meta","Não Atendeu a Meta") -> #DIV/0!
A11: 46276 | B11: NXW6G67 | D11: Marinaldo | E11: 4224.17 | F11: 96676.42 | G11: 879 | H11: =Tabela35[[#This Row],[Valor Frete]]/Tabela35[[#This Row],[Valor Mercadoria]] -> 0.043693902 | K11: =Tabela35[[#This Row],[Hr Chegada]]-Tabela35[[#This Row],[Hr Saida]] -> 0 | L11: 500 | M11: =Tabela35[[#This Row],[Frete]]/Tabela35[[#This Row],[Valor Frete]] -> 0.11836645 | Q11: =Tabela35[[#This Row],[Qtde Entregas]]-Tabela35[[#This Row],[Entregas Realizadas]] -> 0 | R11: =Tabela35[[#This Row],[Entregas Realizadas]]/Tabela35[[#This Row],[Qtde Entregas]] -> #DIV/0! | S11: =IF(Tabela35[[#This Row],[% Entrega]]>=96%,"Atendeu a Meta","Não Atendeu a Meta") -> #DIV/0!
A12: 46280 | B12: NXW6G67 | D12: Marinaldo | E12: 3592.03 | F12: 44758.63 | H12: =Tabela35[[#This Row],[Valor Frete]]/Tabela35[[#This Row],[Valor Mercadoria]] -> 0.08025335 | K12: =Tabela35[[#This Row],[Hr Chegada]]-Tabela35[[#This Row],[Hr Saida]] -> 0 | L12: 500 | M12: =Tabela35[[#This Row],[Frete]]/Tabela35[[#This Row],[Valor Frete]] -> 0.13919706 | Q12: =Tabela35[[#This Row],[Qtde Entregas]]-Tabela35[[#This Row],[Entregas Realizadas]] -> 0 | R12: =Tabela35[[#This Row],[Entregas Realizadas]]/Tabela35[[#This Row],[Qtde Entregas]] -> #DIV/0! | S12: =IF(Tabela35[[#This Row],[% Entrega]]>=96%,"Atendeu a Meta","Não Atendeu a Meta") -> #DIV/0!
A13: 46281 | B13: NXW6G67 | D13: Marinaldo | E13: 4998.43 | F13: 82581.28 | H13: =Tabela35[[#This Row],[Valor Frete]]/Tabela35[[#This Row],[Valor Mercadoria]] -> 0.060527398 | K13: =Tabela35[[#This Row],[Hr Chegada]]-Tabela35[[#This Row],[Hr Saida]] -> 0 | L13: 500 | M13: =Tabela35[[#This Row],[Frete]]/Tabela35[[#This Row],[Valor Frete]] -> 0.10003141 | Q13: =Tabela35[[#This Row],[Qtde Entregas]]-Tabela35[[#This Row],[Entregas Realizadas]] -> 0 | R13: =Tabela35[[#This Row],[Entregas Realizadas]]/Tabela35[[#This Row],[Qtde Entregas]] -> #DIV/0! | S13: =IF(Tabela35[[#This Row],[% Entrega]]>=96%,"Atendeu a Meta","Não Atendeu a Meta") -> #DIV/0!
A14: 46282 | B14: NXW6G67 | D14: Marinaldo | E14: 3850.15 | F14: 59193.01 | G14: 537 | H14: =Tabela35[[#This Row],[Valor Frete]]/Tabela35[[#This Row],[Valor Mercadoria]] -> 0.065043998 | K14: =Tabela35[[#This Row],[Hr Chegada]]-Tabela35[[#This Row],[Hr Saida]] -> 0 | L14: 500 | M14: =Tabela35[[#This Row],[Frete]]/Tabela35[[#This Row],[Valor Frete]] -> 0.12986507 | O14: 16 | P14: 14 | Q14: =Tabela35[[#This Row],[Qtde Entregas]]-Tabela35[[#This Row],[Entregas Realizadas]] -> 2 | R14: =Tabela35[[#This Row],[Entregas Realizadas]]/Tabela35[[#This Row],[Qtde Entregas]] -> 0.875 | S14: =IF(Tabela35[[#This Row],[% Entrega]]>=96%,"Atendeu a Meta","Não Atendeu a Meta") -> Não Atendeu a Meta | T14: Belém | U14: 2
A15: 46283 | B15: NXW6G67 | D15: Marinaldo | E15: 6994.8 | F15: 202752.86 | G15: 1833 | H15: =Tabela35[[#This Row],[Valor Frete]]/Tabela35[[#This Row],[Valor Mercadoria]] -> 0.034499143 | K15: =Tabela35[[#This Row],[Hr Chegada]]-Tabela35[[#This Row],[Hr Saida]] -> 0 | L15: 500 | M15: =Tabela35[[#This Row],[Frete]]/Tabela35[[#This Row],[Valor Frete]] -> 0.071481672 | Q15: =Tabela35[[#This Row],[Qtde Entregas]]-Tabela35[[#This Row],[Entregas Realizadas]] -> 0 | R15: =Tabela35[[#This Row],[Entregas Realizadas]]/Tabela35[[#This Row],[Qtde Entregas]] -> #DIV/0! | S15: =IF(Tabela35[[#This Row],[% Entrega]]>=96%,"Atendeu a Meta","Não Atendeu a Meta") -> #DIV/0!
A16: 46287 | B16: NXW6G67 | D16: Marinaldo | E16: 6537.08 | F16: 70656.17 | G16: 2255 | H16: =Tabela35[[#This Row],[Valor Frete]]/Tabela35[[#This Row],[Valor Mercadoria]] -> 0.092519592 | K16: =Tabela35[[#This Row],[Hr Chegada]]-Tabela35[[#This Row],[Hr Saida]] -> 0 | L16: 500 | M16: =Tabela35[[#This Row],[Frete]]/Tabela35[[#This Row],[Valor Frete]] -> 0.076486749 | O16: 11 | P16: 11 | Q16: =Tabela35[[#This Row],[Qtde Entregas]]-Tabela35[[#This Row],[Entregas Realizadas]] -> 0 | R16: =Tabela35[[#This Row],[Entregas Realizadas]]/Tabela35[[#This Row],[Qtde Entregas]] -> 1 | S16: =IF(Tabela35[[#This Row],[% Entrega]]>=96%,"Atendeu a Meta","Não Atendeu a Meta") -> Atendeu a Meta
A17: 46287 | B17: JVY9G53 | D17: Pedro | E17: 4118.54 | F17: 62885.27 | G17: 632 | H17: =Tabela35[[#This Row],[Valor Frete]]/Tabela35[[#This Row],[Valor Mercadoria]] -> 0.065492921 | K17: =Tabela35[[#This Row],[Hr Chegada]]-Tabela35[[#This Row],[Hr Saida]] -> 0 | L17: 500 | M17: =Tabela35[[#This Row],[Frete]]/Tabela35[[#This Row],[Valor Frete]] -> 0.12140224 | O17: 5 | P17: 5 | Q17: =Tabela35[[#This Row],[Qtde Entregas]]-Tabela35[[#This Row],[Entregas Realizadas]] -> 0 | R17: =Tabela35[[#This Row],[Entregas Realizadas]]/Tabela35[[#This Row],[Qtde Entregas]] -> 1 | S17: =IF(Tabela35[[#This Row],[% Entrega]]>=96%,"Atendeu a Meta","Não Atendeu a Meta") -> Atendeu a Meta
A18: 46288 | B18: NXW6G67 | D18: Marinaldo | E18: 4151.14 | F18: 51812.79 | G18: 631 | H18: =Tabela35[[#This Row],[Valor Frete]]/Tabela35[[#This Row],[Valor Mercadoria]] -> 0.080118056 | K18: =Tabela35[[#This Row],[Hr Chegada]]-Tabela35[[#This Row],[Hr Saida]] -> 0 | L18: 500 | M18: =Tabela35[[#This Row],[Frete]]/Tabela35[[#This Row],[Valor Frete]] -> 0.12044884 | O18: 11 | P18: 11 | Q18: =Tabela35[[#This Row],[Qtde Entregas]]-Tabela35[[#This Row],[Entregas Realizadas]] -> 0 | R18: =Tabela35[[#This Row],[Entregas Realizadas]]/Tabela35[[#This Row],[Qtde Entregas]] -> 1 | S18: =IF(Tabela35[[#This Row],[% Entrega]]>=96%,"Atendeu a Meta","Não Atendeu a Meta") -> Atendeu a Meta
A19: 46289 | B19: NXW6G67 | D19: Marinaldo | E19: 3779.58 | F19: 77696.94 | G19: 718 | H19: =Tabela35[[#This Row],[Valor Frete]]/Tabela35[[#This Row],[Valor Mercadoria]] -> 0.048645159 | K19: =Tabela35[[#This Row],[Hr Chegada]]-Tabela35[[#This Row],[Hr Saida]] -> 0 | L19: 500 | M19: =Tabela35[[#This Row],[Frete]]/Tabela35[[#This Row],[Valor Frete]] -> 0.13228983 | O19: 14 | P19: 14 | Q19: =Tabela35[[#This Row],[Qtde Entregas]]-Tabela35[[#This Row],[Entregas Realizadas]] -> 0 | R19: =Tabela35[[#This Row],[Entregas Realizadas]]/Tabela35[[#This Row],[Qtde Entregas]] -> 1 | S19: =IF(Tabela35[[#This Row],[% Entrega]]>=96%,"Atendeu a Meta","Não Atendeu a Meta") -> Atendeu a Meta | T19: 0 | U19: 38
A20: 46290 | B20: NXW6G67 | D20: Marinaldo | E20: 10761.38 | F20: 181084.37 | G20: 2461 | H20: =Tabela35[[#This Row],[Valor Frete]]/Tabela35[[#This Row],[Valor Mercadoria]] -> 0.059427437 | K20: =Tabela35[[#This Row],[Hr Chegada]]-Tabela35[[#This Row],[Hr Saida]] -> 0 | L20: 500 | M20: =Tabela35[[#This Row],[Frete]]/Tabela35[[#This Row],[Valor Frete]] -> 0.046462443 | O20: 28 | P20: 28 | Q20: =Tabela35[[#This Row],[Qtde Entregas]]-Tabela35[[#This Row],[Entregas Realizadas]] -> 0 | R20: =Tabela35[[#This Row],[Entregas Realizadas]]/Tabela35[[#This Row],[Qtde Entregas]] -> 1 | S20: =IF(Tabela35[[#This Row],[% Entrega]]>=96%,"Atendeu a Meta","Não Atendeu a Meta") -> Atendeu a Meta | T20: 0 | U20: 38,38,38
A21: 46294 | B21: NSE5B85 | D21: Silvio | H21: =Tabela35[[#This Row],[Valor Frete]]/Tabela35[[#This Row],[Valor Mercadoria]] -> #DIV/0! | K21: =Tabela35[[#This Row],[Hr Chegada]]-Tabela35[[#This Row],[Hr Saida]] -> 0 | M21: =Tabela35[[#This Row],[Frete]]/Tabela35[[#This Row],[Valor Frete]] -> #DIV/0! | Q21: =Tabela35[[#This Row],[Qtde Entregas]]-Tabela35[[#This Row],[Entregas Realizadas]] -> 0 | R21: =Tabela35[[#This Row],[Entregas Realizadas]]/Tabela35[[#This Row],[Qtde Entregas]] -> #DIV/0! | S21: =IF(Tabela35[[#This Row],[% Entrega]]>=96%,"Atendeu a Meta","Não Atendeu a Meta") -> #DIV/0!
A22: 46295 | B22: NSE5B85 | D22: Silvio | H22: =Tabela35[[#This Row],[Valor Frete]]/Tabela35[[#This Row],[Valor Mercadoria]] -> #DIV/0! | K22: =Tabela35[[#This Row],[Hr Chegada]]-Tabela35[[#This Row],[Hr Saida]] -> 0 | M22: =Tabela35[[#This Row],[Frete]]/Tabela35[[#This Row],[Valor Frete]] -> #DIV/0! | Q22: =Tabela35[[#This Row],[Qtde Entregas]]-Tabela35[[#This Row],[Entregas Realizadas]] -> 0 | R22: =Tabela35[[#This Row],[Entregas Realizadas]]/Tabela35[[#This Row],[Qtde Entregas]] -> #DIV/0! | S22: =IF(Tabela35[[#This Row],[% Entrega]]>=96%,"Atendeu a Meta","Não Atendeu a Meta") -> #DIV/0!
A23: 46296 | B23: NXW6G67 | D23: Marinaldo | E23: 9007.21 | F23: 179512.59 | G23: 2015 | H23: =Tabela35[[#This Row],[Valor Frete]]/Tabela35[[#This Row],[Valor Mercadoria]] -> 0.050175924 | K23: =Tabela35[[#This Row],[Hr Chegada]]-Tabela35[[#This Row],[Hr Saida]] -> 0 | L23: 500 | M23: =Tabela35[[#This Row],[Frete]]/Tabela35[[#This Row],[Valor Frete]] -> 0.055511085 | Q23: =Tabela35[[#This Row],[Qtde Entregas]]-Tabela35[[#This Row],[Entregas Realizadas]] -> 0 | R23: =Tabela35[[#This Row],[Entregas Realizadas]]/Tabela35[[#This Row],[Qtde Entregas]] -> #DIV/0! | S23: =IF(Tabela35[[#This Row],[% Entrega]]>=96%,"Atendeu a Meta","Não Atendeu a Meta") -> #DIV/0!
A24: 46301 | B24: NXW6G67 | D24: Marinaldo | E24: 6185.78 | F24: 89820.8 | H24: =Tabela35[[#This Row],[Valor Frete]]/Tabela35[[#This Row],[Valor Mercadoria]] -> 0.068868013 | K24: =Tabela35[[#This Row],[Hr Chegada]]-Tabela35[[#This Row],[Hr Saida]] -> 0 | L24: 500 | M24: =Tabela35[[#This Row],[Frete]]/Tabela35[[#This Row],[Valor Frete]] -> 0.08083055 | Q24: =Tabela35[[#This Row],[Qtde Entregas]]-Tabela35[[#This Row],[Entregas Realizadas]] -> 0 | R24: =Tabela35[[#This Row],[Entregas Realizadas]]/Tabela35[[#This Row],[Qtde Entregas]] -> #DIV/0! | S24: =IF(Tabela35[[#This Row],[% Entrega]]>=96%,"Atendeu a Meta","Não Atendeu a Meta") -> #DIV/0!
A25: 46302 | B25: NXW6G67 | D25: Marinaldo | E25: 8104.3 | F25: 95783.11 | H25: =Tabela35[[#This Row],[Valor Frete]]/Tabela35[[#This Row],[Valor Mercadoria]] -> 0.084610951 | K25: =Tabela35[[#This Row],[Hr Chegada]]-Tabela35[[#This Row],[Hr Saida]] -> 0 | L25: 500 | M25: =Tabela35[[#This Row],[Frete]]/Tabela35[[#This Row],[Valor Frete]] -> 0.061695643 | O25: 16 | P25: 16 | Q25: =Tabela35[[#This Row],[Qtde Entregas]]-Tabela35[[#This Row],[Entregas Realizadas]] -> 0 | R25: =Tabela35[[#This Row],[Entregas Realizadas]]/Tabela35[[#This Row],[Qtde Entregas]] -> 1 | S25: =IF(Tabela35[[#This Row],[% Entrega]]>=96%,"Atendeu a Meta","Não Atendeu a Meta") -> Atendeu a Meta | T25: Belém | U25: 38
A26: 46303 | B26: NXW6G67 | D26: Marinaldo | E26: 5994.53 | F26: 131439.71 | G26: 1808 | H26: =Tabela35[[#This Row],[Valor Frete]]/Tabela35[[#This Row],[Valor Mercadoria]] -> 0.045606689 | K26: =Tabela35[[#This Row],[Hr Chegada]]-Tabela35[[#This Row],[Hr Saida]] -> 0 | L26: 500 | M26: =Tabela35[[#This Row],[Frete]]/Tabela35[[#This Row],[Valor Frete]] -> 0.083409375 | N26: 359 | O26: 19 | P26: 19 | Q26: =Tabela35[[#This Row],[Qtde Entregas]]-Tabela35[[#This Row],[Entregas Realizadas]] -> 0 | R26: =Tabela35[[#This Row],[Entregas Realizadas]]/Tabela35[[#This Row],[Qtde Entregas]] -> 1 | S26: =IF(Tabela35[[#This Row],[% Entrega]]>=96%,"Atendeu a Meta","Não Atendeu a Meta") -> Atendeu a Meta | T26: Belém | U26: 0 | V26: 0
A27: 46304 | H27: =Tabela35[[#This Row],[Valor Frete]]/Tabela35[[#This Row],[Valor Mercadoria]] -> #DIV/0! | K27: =Tabela35[[#This Row],[Hr Chegada]]-Tabela35[[#This Row],[Hr Saida]] -> 0 | M27: =Tabela35[[#This Row],[Frete]]/Tabela35[[#This Row],[Valor Frete]] -> #DIV/0! | Q27: =Tabela35[[#This Row],[Qtde Entregas]]-Tabela35[[#This Row],[Entregas Realizadas]] -> 0 | R27: =Tabela35[[#This Row],[Entregas Realizadas]]/Tabela35[[#This Row],[Qtde Entregas]] -> #DIV/0! | S27: =IF(Tabela35[[#This Row],[% Entrega]]>=96%,"Atendeu a Meta","Não Atendeu a Meta") -> #DIV/0!

Sheet jan_26 (2)
A1: Data | B1: Ano | C1: Mês | D1: Placa | E1: Rota | F1: Motorista | G1: Valor Frete | H1: Valor Mercadoria | I1: Peso | J1: % Frete | K1: Hr Saida | L1: Hr Chegada | M1: Tempo | N1: Km Saída | O1: Km Chegada | P1: Km/Dia | Q1: Vols | R1: Entregas | S1: Realizadas | T1: Retornadas | U1: % Entrega | V1: Meta | W1: Cidade Destino | X1: Nfs Voltaram | Y1: Ocorrência
A2: 46237 | B2: =YEAR(Tabela32[[#This Row],[Data]]) -> 2026 | C2: =MONTH(Tabela32[[#This Row],[Data]]) -> 8 | D2: RKV1173 | E2: 3 | F2: =IFERROR(VLOOKUP(Tabela32[[#This Row],[Placa]],Planilha2!$A$1:$B$12,2,0),"") -> William | G2: 8845.4 | H2: 229478.26 | I2: 2224 | J2: =IFERROR(Tabela32[[#This Row],[Valor Frete]]/Tabela32[[#This Row],[Valor Mercadoria]],"") -> 0.038545699 | K2: 0.27083333 | L2: 0.75694444 | M2: =Tabela32[[#This Row],[Hr Chegada]]-Tabela32[[#This Row],[Hr Saida]] -> 0.48611111 | N2: 123165 | O2: 123227 | P2: =Tabela32[[#This Row],[Km Chegada]]-Tabela32[[#This Row],[Km Saída]] -> 62 | Q2: 208 | R2: 17 | S2: 17 | T2: =Tabela32[[#This Row],[Entregas]]-Tabela32[[#This Row],[Realizadas]] -> 0 | U2: =Tabela32[[#This Row],[Realizadas]]/Tabela32[[#This Row],[Entregas]] -> 1 | V2: =IF(Tabela32[[#This Row],[% Entrega]]>=96%,"Atendeu a Meta","Não Atendeu a Meta") -> Atendeu a Meta | W2: Belém | X2: 0 | Y2: 0
A3: 46237 | B3: =YEAR(Tabela32[[#This Row],[Data]]) -> 2026 | C3: =MONTH(Tabela32[[#This Row],[Data]]) -> 8 | D3: IYD7460 | E3: 1 | F3: =IFERROR(VLOOKUP(Tabela32[[#This Row],[Placa]],Planilha2!$A$1:$B$12,2,0),"") -> Paulo | G3: 4361.26 | H3: 46788.62 | I3: 519 | J3: =IFERROR(Tabela32[[#This Row],[Valor Frete]]/Tabela32[[#This Row],[Valor Mercadoria]],"") -> 0.093211982 | K3: 0.29166667 | L3: 0.70833333 | M3: =Tabela32[[#This Row],[Hr Chegada]]-Tabela32[[#This Row],[Hr Saida]] -> 0.41666667 | N3: 153358 | O3: 153447 | P3: =Tabela32[[#This Row],[Km Chegada]]-Tabela32[[#This Row],[Km Saída]] -> 89 | Q3: 100 | R3: 14 | S3: 14 | T3: =Tabela32[[#This Row],[Entregas]]-Tabela32[[#This Row],[Realizadas]] -> 0 | U3: =Tabela32[[#This Row],[Realizadas]]/Tabela32[[#This Row],[Entregas]] -> 1 | V3: =IF(Tabela32[[#This Row],[% Entrega]]>=96%,"Atendeu a Meta","Não Atendeu a Meta") -> Atendeu a Meta | W3: Belém | X3: 0 | Y3: 0
A4: 46237 | B4: =YEAR(Tabela32[[#This Row],[Data]]) -> 2026 | C4: =MONTH(Tabela32[[#This Row],[Data]]) -> 8 | D4: TRD2G21 | E4: 1 | F4: =IFERROR(VLOOKUP(Tabela32[[#This Row],[Placa]],Planilha2!$A$1:$B$12,2,0),"") -> Arnaldo | G4: 10990.49 | H4: 239686.28 | I4: 2245 | J4: =IFERROR(Tabela32[[#This Row],[Valor Frete]]/Tabela32[[#This Row],[Valor Mercadoria]],"") -> 0.045853647 | K4: 0.29166667 | L4: 0.75 | M4: =Tabela32[[#This Row],[Hr Chegada]]-Tabela32[[#This Row],[Hr Saida]] -> 0.45833333 | N4: 11485 | O4: 11546 | P4: =Tabela32[[#This Row],[Km Chegada]]-Tabela32[[#This Row],[Km Saída]] -> 61 | Q4: 315 | R4: 34 | S4: 34 | T4: =Tabela32[[#This Row],[Entregas]]-Tabela32[[#This Row],[Realizadas]] -> 0 | U4: =Tabela32[[#This Row],[Realizadas]]/Tabela32[[#This Row],[Entregas]] -> 1 | V4: =IF(Tabela32[[#This Row],[% Entrega]]>=96%,"Atendeu a Meta","Não Atendeu a Meta") -> Atendeu a Meta | W4: Belém | X4: 0 | Y4: 0
A5: 46237 | B5: =YEAR(Tabela32[[#This Row],[Data]]) -> 2026 | C5: =MONTH(Tabela32[[#This Row],[Data]]) -> 8 | D5: LTY8B39 | E5: 2 | F5: =IFERROR(VLOOKUP(Tabela32[[#This Row],[Placa]],Planilha2!$A$1:$B$12,2,0),"") -> Gilberto | G5: 12153.58 | H5: 209648.96 | I5: 2509 | J5: =IFERROR(Tabela32[[#This Row],[Valor Frete]]/Tabela32[[#This Row],[Valor Mercadoria]],"") -> 0.057971096 | K5: 0.29166667 | L5: 0.75 | M5: =Tabela32[[#This Row],[Hr Chegada]]-Tabela32[[#This Row],[Hr Saida]] -> 0.45833333 | N5: 117070 | O5: 117125 | P5: =Tabela32[[#This Row],[Km Chegada]]-Tabela32[[#This Row],[Km Saída]] -> 55 | Q5: 383 | R5: 42 | S5: 42 | T5: =Tabela32[[#This Row],[Entregas]]-Tabela32[[#This Row],[Realizadas]] -> 0 | U5: =Tabela32[[#This Row],[Realizadas]]/Tabela32[[#This Row],[Entregas]] -> 1 | V5: =IF(Tabela32[[#This Row],[% Entrega]]>=96%,"Atendeu a Meta","Não Atendeu a Meta") -> Atendeu a Meta | W5: Belém | X5: 0 | Y5: 0
A6: 46237 | B6: =YEAR(Tabela32[[#This Row],[Data]]) -> 2026 | C6: =MONTH(Tabela32[[#This Row],[Data]]) -> 8 | D6: IXY4731 | E6: 5 | F6: =IFERROR(VLOOKUP(Tabela32[[#This Row],[Placa]],Planilha2!$A$1:$B$12,2,0),"") -> Osvaldo | G6: 5878.32 | H6: 122432.31 | I6: 1838 | J6: =IFERROR(Tabela32[[#This Row],[Valor Frete]]/Tabela32[[#This Row],[Valor Mercadoria]],"") -> 0.048012816 | K6: 0.29166667 | L6: 0.70833333 | M6: =Tabela32[[#This Row],[Hr Chegada]]-Tabela32[[#This Row],[Hr Saida]] -> 0.41666667 | N6: 140571 | O6: 140635 | P6: =Tabela32[[#This Row],[Km Chegada]]-Tabela32[[#This Row],[Km Saída]] -> 64 | Q6: 3 | R6: 2 | S6: 2 | T6: =Tabela32[[#This Row],[Entregas]]-Tabela32[[#This Row],[Realizadas]] -> 0 | U6: =Tabela32[[#This Row],[Realizadas]]/Tabela32[[#This Row],[Entregas]] -> 1 | V6: =IF(Tabela32[[#This Row],[% Entrega]]>=96%,"Atendeu a Meta","Não Atendeu a Meta") -> Atendeu a Meta | W6: Belém | X6: 0 | Y6: 0
A7: 46237 | B7: =YEAR(Tabela32[[#This Row],[Data]]) -> 2026 | C7: =MONTH(Tabela32[[#This Row],[Data]]) -> 8 | D7: IUG8767 | E7: 1 | F7: =IFERROR(VLOOKUP(Tabela32[[#This Row],[Placa]],Planilha2!$A$1:$B$12,2,0),"") -> Jerson | G7: 11704.49 | H7: 191260.58 | I7: 2762 | J7: =IFERROR(Tabela32[[#This Row],[Valor Frete]]/Tabela32[[#This Row],[Valor Mercadoria]],"") -> 0.061196562 | K7: 0.29166667 | L7: 0.75 | M7: =Tabela32[[#This Row],[Hr Chegada]]-Tabela32[[#This Row],[Hr Saida]] -> 0.45833333 | N7: 278755 | O7: 278800 | P7: =Tabela32[[#This Row],[Km Chegada]]-Tabela32[[#This Row],[Km Saída]] -> 45 | Q7: 297 | R7: 22 | S7: 22 | T7: =Tabela32[[#This Row],[Entregas]]-Tabela32[[#This Row],[Realizadas]] -> 0 | U7: =Tabela32[[#This Row],[Realizadas]]/Tabela32[[#This Row],[Entregas]] -> 1 | V7: =IF(Tabela32[[#This Row],[% Entrega]]>=96%,"Atendeu a Meta","Não Atendeu a Meta") -> Atendeu a Meta | W7: Ananindeua | X7: 0 | Y7: 0
A8: 46237 | B8: =YEAR(Tabela32[[#This Row],[Data]]) -> 2026 | C8: =MONTH(Tabela32[[#This Row],[Data]]) -> 8 | D8: IUG8744 | E8: 4 | F8: =IFERROR(VLOOKUP(Tabela32[[#This Row],[Placa]],Planilha2!$A$1:$B$12,2,0),"") -> Sandro | G8: 2038.29 | H8: 29918.46 | I8: 402 | J8: =IFERROR(Tabela32[[#This Row],[Valor Frete]]/Tabela32[[#This Row],[Valor Mercadoria]],"") -> 0.068128172 | K8: 0.29166667 | L8: 0.75694444 | M8: =Tabela32[[#This Row],[Hr Chegada]]-Tabela32[[#This Row],[Hr Saida]] -> 0.46527778 | N8: 273803 | O8: 273946 | P8: =Tabela32[[#This Row],[Km Chegada]]-Tabela32[[#This Row],[Km Saída]] -> 143 | Q8: 25 | R8: 7 | S8: 7 | T8: =Tabela32[[#This Row],[Entregas]]-Tabela32[[#This Row],[Realizadas]] -> 0 | U8: =Tabela32[[#This Row],[Realizadas]]/Tabela32[[#This Row],[Entregas]] -> 1 | V8: =IF(Tabela32[[#This Row],[% Entrega]]>=96%,"Atendeu a Meta","Não Atendeu a Meta") -> Atendeu a Meta | W8: Belém | X8: 0 | Y8: 0
A9: 46237 | B9: =YEAR(Tabela32[[#This Row],[Data]]) -> 2026 | C9: =MONTH(Tabela32[[#This Row],[Data]]) -> 8 | D9: IUG8882 | E9: 1 | F9: =IFERROR(VLOOKUP(Tabela32[[#This Row],[Placa]],Planilha2!$A$1:$B$12,2,0),"") -> Wesley | G9: 6077.29 | H9: 118495.96 | I9: 859 | J9: =IFERROR(Tabela32[[#This Row],[Valor Frete]]/Tabela32[[#This Row],[Valor Mercadoria]],"") -> 0.051286896 | K9: 0.29166667 | L9: 0.75347222 | M9: =Tabela32[[#This Row],[Hr Chegada]]-Tabela32[[#This Row],[Hr Saida]] -> 0.46180556 | N9: 302136 | O9: 302272 | P9: =Tabela32[[#This Row],[Km Chegada]]-Tabela32[[#This Row],[Km Saída]] -> 136 | Q9: 116 | R9: 30 | S9: 30 | T9: =Tabela32[[#This Row],[Entregas]]-Tabela32[[#This Row],[Realizadas]] -> 0 | U9: =Tabela32[[#This Row],[Realizadas]]/Tabela32[[#This Row],[Entregas]] -> 1 | V9: =IF(Tabela32[[#This Row],[% Entrega]]>=96%,"Atendeu a Meta","Não Atendeu a Meta") -> Atendeu a Meta | W9: Castanhal | X9: 0 | Y9: 0
A10: 46237 | B10: =YEAR(Tabela32[[#This Row],[Data]]) -> 2026 | C10: =MONTH(Tabela32[[#This Row],[Data]]) -> 8 | D10: IVX5G13 | E10: 1 | F10: =IFERROR(VLOOKUP(Tabela32[[#This Row],[Placa]],Planilha2!$A$1:$B$12,2,0),"") -> Heremilton | G10: 32724.35 | H10: 808017.95 | I10: 101 | J10: =IFERROR(Tabela32[[#This Row],[Valor Frete]]/Tabela32[[#This Row],[Valor Mercadoria]],"") -> 0.040499533 | K10: 0.25 | L10: 0.75 | M10: =Tabela32[[#This Row],[Hr Chegada]]-Tabela32[[#This Row],[Hr Saida]] -> 0.5 | N10: 363975 | O10: 364007 | P10: =Tabela32[[#This Row],[Km Chegada]]-Tabela32[[#This Row],[Km Saída]] -> 32 | Q10: 101 | R10: 6 | S10: 6 | T10: =Tabela32[[#This Row],[Entregas]]-Tabela32[[#This Row],[Realizadas]] -> 0 | U10: =Tabela32[[#This Row],[Realizadas]]/Tabela32[[#This Row],[Entregas]] -> 1 | V10: =IF(Tabela32[[#This Row],[% Entrega]]>=96%,"Atendeu a Meta","Não Atendeu a Meta") -> Atendeu a Meta | W10: Castanhal | X10: 0 | Y10: 0
A11: 46237 | B11: =YEAR(Tabela32[[#This Row],[Data]]) -> 2026 | C11: =MONTH(Tabela32[[#This Row],[Data]]) -> 8 | D11: IUG8855 | E11: 1 | F11: =IFERROR(VLOOKUP(Tabela32[[#This Row],[Placa]],Planilha2!$A$1:$B$12,2,0),"") -> Rosinaldo | G11: 12477.04 | H11: 472202.58 | I11: 2812 | J11: =IFERROR(Tabela32[[#This Row],[Valor Frete]]/Tabela32[[#This Row],[Valor Mercadoria]],"") -> 0.026423066 | K11: 0.29166667 | L11: 0.70833333 | M11: =Tabela32[[#This Row],[Hr Chegada]]-Tabela32[[#This Row],[Hr Saida]] -> 0.41666667 | N11: 289370 | O11: 289406 | P11: =Tabela32[[#This Row],[Km Chegada]]-Tabela32[[#This Row],[Km Saída]] -> 36 | Q11: 212 | R11: 7 | S11: 7 | T11: =Tabela32[[#This Row],[Entregas]]-Tabela32[[#This Row],[Realizadas]] -> 0 | U11: =Tabela32[[#This Row],[Realizadas]]/Tabela32[[#This Row],[Entregas]] -> 1 | V11: =IF(Tabela32[[#This Row],[% Entrega]]>=96%,"Atendeu a Meta","Não Atendeu a Meta") -> Atendeu a Meta | W11: Belém | X11: 0 | Y11: 0
A12: 46237 | B12: =YEAR(Tabela32[[#This Row],[Data]]) -> 2026 | C12: =MONTH(Tabela32[[#This Row],[Data]]) -> 8 | D12: RJA2C91 | E12: 11 | F12: =IFERROR(VLOOKUP(Tabela32[[#This Row],[Placa]],Planilha2!$A$1:$B$12,2,0),"") -> Edilson | G12: 39898.21 | H12: 223501.93 | I12: 4822 | J12: =IFERROR(Tabela32[[#This Row],[Valor Frete]]/Tabela32[[#This Row],[Valor Mercadoria]],"") -> 0.17851394 | K12: 0.25 | L12: 0.70833333 | M12: =Tabela32[[#This Row],[Hr Chegada]]-Tabela32[[#This Row],[Hr Saida]] -> 0.45833333 | N12: 102828 | O12: 102859 | P12: =Tabela32[[#This Row],[Km Chegada]]-Tabela32[[#This Row],[Km Saída]] -> 31 | Q12: 613 | R12: 6 | S12: 6 | T12: =Tabela32[[#This Row],[Entregas]]-Tabela32[[#This Row],[Realizadas]] -> 0 | U12: =Tabela32[[#This Row],[Realizadas]]/Tabela32[[#This Row],[Entregas]] -> 1 | V12: =IF(Tabela32[[#This Row],[% Entrega]]>=96%,"Atendeu a Meta","Não Atendeu a Meta") -> Atendeu a Meta | W12: Benevides | X12: 0 | Y12: 0
A13: 46238 | B13: =YEAR(Tabela32[[#This Row],[Data]]) -> 2026 | C13: =MONTH(Tabela32[[#This Row],[Data]]) -> 8 | D13: LTY8B39 | E13: 2 | F13: =IFERROR(VLOOKUP(Tabela32[[#This Row],[Placa]],Planilha2!$A$1:$B$12,2,0),"") -> Gilberto | G13: 6969.57 | H13: 101194.09 | I13: 1533 | J13: =IFERROR(Tabela32[[#This Row],[Valor Frete]]/Tabela32[[#This Row],[Valor Mercadoria]],"") -> 0.068873291 | K13: 0.25 | L13: 0.66666667 | M13: =Tabela32[[#This Row],[Hr Chegada]]-Tabela32[[#This Row],[Hr Saida]] -> 0.41666667 | N13: 117009 | O13: 117070 | P13: =Tabela32[[#This Row],[Km Chegada]]-Tabela32[[#This Row],[Km Saída]] -> 61 | Q13: 296 | R13: 33 | S13: 33 | T13: =Tabela32[[#This Row],[Entregas]]-Tabela32[[#This Row],[Realizadas]] -> 0 | U13: =Tabela32[[#This Row],[Realizadas]]/Tabela32[[#This Row],[Entregas]] -> 1 | V13: =IF(Tabela32[[#This Row],[% Entrega]]>=96%,"Atendeu a Meta","Não Atendeu a Meta") -> Atendeu a Meta | W13: Belém | X13: 0 | Y13: 0
... A37: 46241 | B37: =YEAR(Tabela32[[#This Row],[Data]]) -> 2026 | C37: =MONTH(Tabela32[[#This Row],[Data]]) -> 8 | D37: RKV1173 | E37: 3 | F37: =IFERROR(VLOOKUP(Tabela32[[#This Row],[Placa]],Planilha2!$A$1:$B$12,2,0),"") -> William | G37: 5239.71 | H37: 175862.76 | I37: 690 | J37: =IFERROR(Tabela32[[#This Row],[Valor Frete]]/Tabela32[[#This Row],[Valor Mercadoria]],"") -> 0.029794312 | K37: 0.29166667 | L37: 0.72222222 | M37: =Tabela32[[#This Row],[Hr Chegada]]-Tabela32[[#This Row],[Hr Saida]] -> 0.43055556 | N37: 123656 | O37: 123713 | P37: =Tabela32[[#This Row],[Km Chegada]]-Tabela32[[#This Row],[Km Saída]] -> 57 | Q37: 165 | R37: 22 | S37: 22 | T37: =Tabela32[[#This Row],[Entregas]]-Tabela32[[#This Row],[Realizadas]] -> 0 | U37: =Tabela32[[#This Row],[Realizadas]]/Tabela32[[#This Row],[Entregas]] -> 1 | V37: =IF(Tabela32[[#This Row],[% Entrega]]>=96%,"Atendeu a Meta","Não Atendeu a Meta") -> Atendeu a Meta | W37: Belém | X37: 0 | Y37: 0
A38: 46241 | B38: =YEAR(Tabela32[[#This Row],[Data]]) -> 2026 | C38: =MONTH(Tabela32[[#This Row],[Data]]) -> 8 | D38: IUG8855 | E38: 1 | F38: =IFERROR(VLOOKUP(Tabela32[[#This Row],[Placa]],Planilha2!$A$1:$B$12,2,0),"") -> Rosinaldo | G38: 4663.5 | H38: 77594.32 | I38: 1104 | J38: =IFERROR(Tabela32[[#This Row],[Valor Frete]]/Tabela32[[#This Row],[Valor Mercadoria]],"") -> 0.060101049 | K38: 0.29166667 | L38: 0.73611111 | M38: =Tabela32[[#This Row],[Hr Chegada]]-Tabela32[[#This Row],[Hr Saida]] -> 0.44444444 | N38: 289691 | O38: 289832 | P38: =Tabela32[[#This Row],[Km Chegada]]-Tabela32[[#This Row],[Km Saída]] -> 141 | Q38: 211 | R38: 11 | S38: 11 | T38: =Tabela32[[#This Row],[Entregas]]-Tabela32[[#This Row],[Realizadas]] -> 0 | U38: =Tabela32[[#This Row],[Realizadas]]/Tabela32[[#This Row],[Entregas]] -> 1 | V38: =IF(Tabela32[[#This Row],[% Entrega]]>=96%,"Atendeu a Meta","Não Atendeu a Meta") -> Atendeu a Meta | W38: Ananindeua | X38: 2 | Y38: 38, 9
A39: 46241 | B39: =YEAR(Tabela32[[#This Row],[Data]]) -> 2026 | C39: =MONTH(Tabela32[[#This Row],[Data]]) -> 8 | D39: IXY4731 | E39: 5 | F39: =IFERROR(VLOOKUP(Tabela32[[#This Row],[Placa]],Planilha2!$A$1:$B$12,2,0),"") -> Osvaldo | G39: 6031.63 | H39: 135833.24 | I39: 1147 | J39: =IFERROR(Tabela32[[#This Row],[Valor Frete]]/Tabela32[[#This Row],[Valor Mercadoria]],"") -> 0.044404669 | K39: 0.29166667 | L39: 0.70486111 | M39: =Tabela32[[#This Row],[Hr Chegada]]-Tabela32[[#This Row],[Hr Saida]] -> 0.41319444 | N39: 140811 | O39: 140875 | P39: =Tabela32[[#This Row],[Km Chegada]]-Tabela32[[#This Row],[Km Saída]] -> 64 | Q39: 162 | R39: 21 | S39: 21 | T39: =Tabela32[[#This Row],[Entregas]]-Tabela32[[#This Row],[Realizadas]] -> 0 | U39: =Tabela32[[#This Row],[Realizadas]]/Tabela32[[#This Row],[Entregas]] -> 1 | V39: =IF(Tabela32[[#This Row],[% Entrega]]>=96%,"Atendeu a Meta","Não Atendeu a Meta") -> Atendeu a Meta | W39: Belém | X39: 0 | Y39: 0
A40: 46241 | B40: =YEAR(Tabela32[[#This Row],[Data]]) -> 2026 | C40: =MONTH(Tabela32[[#This Row],[Data]]) -> 8 | D40: IUG8767 | E40: 1 | F40: =IFERROR(VLOOKUP(Tabela32[[#This Row],[Placa]],Planilha2!$A$1:$B$12,2,0),"") -> Jerson | G40: 7320.26 | H40: 115512.41 | I40: 893 | J40: =IFERROR(Tabela32[[#This Row],[Valor Frete]]/Tabela32[[#This Row],[Valor Mercadoria]],"") -> 0.063372065 | K40: 0.29166667 | L40: 0.70625 | M40: =Tabela32[[#This Row],[Hr Chegada]]-Tabela32[[#This Row],[Hr Saida]] -> 0.41458333 | N40: 278928 | O40: 278977 | P40: =Tabela32[[#This Row],[Km Chegada]]-Tabela32[[#This Row],[Km Saída]] -> 49 | Q40: 145 | R40: 25 | S40: 25 | T40: =Tabela32[[#This Row],[Entregas]]-Tabela32[[#This Row],[Realizadas]] -> 0 | U40: =Tabela32[[#This Row],[Realizadas]]/Tabela32[[#This Row],[Entregas]] -> 1 | V40: =IF(Tabela32[[#This Row],[% Entrega]]>=96%,"Atendeu a Meta","Não Atendeu a Meta") -> Atendeu a Meta | W40: Ananindeua | X40: 2 | Y40: 38
A41: 46241 | B41: =YEAR(Tabela32[[#This Row],[Data]]) -> 2026 | C41: =MONTH(Tabela32[[#This Row],[Data]]) -> 8 | D41: IUG8882 | E41: 11 | F41: =IFERROR(VLOOKUP(Tabela32[[#This Row],[Placa]],Planilha2!$A$1:$B$12,2,0),"") -> Wesley | G41: 10933.65 | H41: 109287.82 | I41: 1145 | J41: =IFERROR(Tabela32[[#This Row],[Valor Frete]]/Tabela32[[#This Row],[Valor Mercadoria]],"") -> 0.10004454 | K41: 0.25 | L41: 0.75 | M41: =Tabela32[[#This Row],[Hr Chegada]]-Tabela32[[#This Row],[Hr Saida]] -> 0.5 | N41: 302561 | O41: 302691 | P41: =Tabela32[[#This Row],[Km Chegada]]-Tabela32[[#This Row],[Km Saída]] -> 130 | Q41: 174 | R41: 19 | S41: 19 | T41: =Tabela32[[#This Row],[Entregas]]-Tabela32[[#This Row],[Realizadas]] -> 0 | U41: =Tabela32[[#This Row],[Realizadas]]/Tabela32[[#This Row],[Entregas]] -> 1 | V41: =IF(Tabela32[[#This Row],[% Entrega]]>=96%,"Atendeu a Meta","Não Atendeu a Meta") -> Atendeu a Meta | W41: Castanhal | X41: 0 | Y41: 0
A42: 46241 | B42: =YEAR(Tabela32[[#This Row],[Data]]) -> 2026 | C42: =MONTH(Tabela32[[#This Row],[Data]]) -> 8 | D42: TRD2G21 | E42: 4 | F42: =IFERROR(VLOOKUP(Tabela32[[#This Row],[Placa]],Planilha2!$A$1:$B$12,2,0),"") -> Arnaldo | G42: 7872.43 | H42: 186025.28 | I42: 1408 | J42: =IFERROR(Tabela32[[#This Row],[Valor Frete]]/Tabela32[[#This Row],[Valor Mercadoria]],"") -> 0.042319141 | K42: 0.29166667 | L42: 0.79861111 | M42: =Tabela32[[#This Row],[Hr Chegada]]-Tabela32[[#This Row],[Hr Saida]] -> 0.50694444 | N42: 11703 | O42: 11777 | P42: =Tabela32[[#This Row],[Km Chegada]]-Tabela32[[#This Row],[Km Saída]] -> 74 | Q42: 200 | R42: 25 | S42: 25 | T42: =Tabela32[[#This Row],[Entregas]]-Tabela32[[#This Row],[Realizadas]] -> 0 | U42: =Tabela32[[#This Row],[Realizadas]]/Tabela32[[#This Row],[Entregas]] -> 1 | V42: =IF(Tabela32[[#This Row],[% Entrega]]>=96%,"Atendeu a Meta","Não Atendeu a Meta") -> Atendeu a Meta | W42: Belém | X42: 1 | Y42: 9
A43: 46241 | B43: =YEAR(Tabela32[[#This Row],[Data]]) -> 2026 | C43: =MONTH(Tabela32[[#This Row],[Data]]) -> 8 | D43: LTY8B39 | E43: 2 | F43: =IFERROR(VLOOKUP(Tabela32[[#This Row],[Placa]],Planilha2!$A$1:$B$12,2,0),"") -> Gilberto | G43: 7887.41 | H43: 108376.66 | I43: 942 | J43: =IFERROR(Tabela32[[#This Row],[Valor Frete]]/Tabela32[[#This Row],[Valor Mercadoria]],"") -> 0.072777755 | K43: 0.30555556 | L43: 0.75 | M43: =Tabela32[[#This Row],[Hr Chegada]]-Tabela32[[#This Row],[Hr Saida]] -> 0.44444444 | N43: 117242 | O43: 117317 | P43: =Tabela32[[#This Row],[Km Chegada]]-Tabela32[[#This Row],[Km Saída]] -> 75 | Q43: 149 | R43: 41 | S43: 41 | T43: =Tabela32[[#This Row],[Entregas]]-Tabela32[[#This Row],[Realizadas]] -> 0 | U43: =Tabela32[[#This Row],[Realizadas]]/Tabela32[[#This Row],[Entregas]] -> 1 | V43: =IF(Tabela32[[#This Row],[% Entrega]]>=96%,"Atendeu a Meta","Não Atendeu a Meta") -> Atendeu a Meta | W43: Belém | X43: 0 | Y43: 0
A44: 46242 | B44: =YEAR(Tabela32[[#This Row],[Data]]) -> 2026 | C44: =MONTH(Tabela32[[#This Row],[Data]]) -> 8 | D44: LTY8B39 | E44: 2 | F44: =IFERROR(VLOOKUP(Tabela32[[#This Row],[Placa]],Planilha2!$A$1:$B$12,2,0),"") -> Gilberto | G44: 3303.18 | H44: 38450.28 | I44: 497 | J44: =IFERROR(Tabela32[[#This Row],[Valor Frete]]/Tabela32[[#This Row],[Valor Mercadoria]],"") -> 0.085907827 | K44: 0.29166667 | L44: 0.74305556 | M44: =Tabela32[[#This Row],[Hr Chegada]]-Tabela32[[#This Row],[Hr Saida]] -> 0.45138889 | N44: 117317 | O44: 117363 | P44: =Tabela32[[#This Row],[Km Chegada]]-Tabela32[[#This Row],[Km Saída]] -> 46 | Q44: 86 | R44: 20 | S44: 20 | T44: =Tabela32[[#This Row],[Entregas]]-Tabela32[[#This Row],[Realizadas]] -> 0 | U44: =Tabela32[[#This Row],[Realizadas]]/Tabela32[[#This Row],[Entregas]] -> 1 | V44: =IF(Tabela32[[#This Row],[% Entrega]]>=96%,"Atendeu a Meta","Não Atendeu a Meta") -> Atendeu a Meta | W44: Belém | X44: 0 | Y44: 0
A45: 46244 | B45: =YEAR(Tabela32[[#This Row],[Data]]) -> 2026 | C45: =MONTH(Tabela32[[#This Row],[Data]]) -> 8 | D45: IYD7460 | E45: 1 | F45: =IFERROR(VLOOKUP(Tabela32[[#This Row],[Placa]],Planilha2!$A$1:$B$12,2,0),"") -> Paulo | G45: 1678.55 | H45: 68546.04 | I45: 92 | J45: =IFERROR(Tabela32[[#This Row],[Valor Frete]]/Tabela32[[#This Row],[Valor Mercadoria]],"") -> 0.024487921 | K45: 0.29166667 | L45: 0.43541667 | M45: =Tabela32[[#This Row],[Hr Chegada]]-Tabela32[[#This Row],[Hr Saida]] -> 0.14375 | N45: 153646 | O45: 153677 | P45: =Tabela32[[#This Row],[Km Chegada]]-Tabela32[[#This Row],[Km Saída]] -> 31 | Q45: 82 | R45: 2 | S45: 2 | T45: =Tabela32[[#This Row],[Entregas]]-Tabela32[[#This Row],[Realizadas]] -> 0 | U45: =Tabela32[[#This Row],[Realizadas]]/Tabela32[[#This Row],[Entregas]] -> 1 | V45: =IF(Tabela32[[#This Row],[% Entrega]]>=96%,"Atendeu a Meta","Não Atendeu a Meta") -> Atendeu a Meta | W45: Benevides | X45: 0 | Y45: 0
A46: 46244 | B46: =YEAR(Tabela32[[#This Row],[Data]]) -> 2026 | C46: =MONTH(Tabela32[[#This Row],[Data]]) -> 8 | D46: RJA2C91 | E46: 1 | F46: =IFERROR(VLOOKUP(Tabela32[[#This Row],[Placa]],Planilha2!$A$1:$B$12,2,0),"") -> Edilson | G46: 14208.89 | H46: 556611.81 | I46: 4465 | J46: =IFERROR(Tabela32[[#This Row],[Valor Frete]]/Tabela32[[#This Row],[Valor Mercadoria]],"") -> 0.025527468 | K46: 0.29166667 | L46: 0.73194444 | M46: =Tabela32[[#This Row],[Hr Chegada]]-Tabela32[[#This Row],[Hr Saida]] -> 0.44027778 | N46: 103105 | O46: 103127 | P46: =Tabela32[[#This Row],[Km Chegada]]-Tabela32[[#This Row],[Km Saída]] -> 22 | Q46: 21 | R46: 1 | S46: 1 | T46: =Tabela32[[#This Row],[Entregas]]-Tabela32[[#This Row],[Realizadas]] -> 0 | U46: =Tabela32[[#This Row],[Realizadas]]/Tabela32[[#This Row],[Entregas]] -> 1 | V46: =IF(Tabela32[[#This Row],[% Entrega]]>=96%,"Atendeu a Meta","Não Atendeu a Meta") -> Atendeu a Meta | W46: Ananindeua | X46: 0 | Y46: 0
A47: 46244 | B47: =YEAR(Tabela32[[#This Row],[Data]]) -> 2026 | C47: =MONTH(Tabela32[[#This Row],[Data]]) -> 8 | D47: IYD7460 | E47: 3 | F47: =IFERROR(VLOOKUP(Tabela32[[#This Row],[Placa]],Planilha2!$A$1:$B$12,2,0),"") -> Paulo | G47: 3490.5 | H47: 54931.47 | I47: 540 | J47: =IFERROR(Tabela32[[#This Row],[Valor Frete]]/Tabela32[[#This Row],[Valor Mercadoria]],"") -> 0.063542811 | K47: 0.29166667 | L47: 0.72569444 | M47: =Tabela32[[#This Row],[Hr Chegada]]-Tabela32[[#This Row],[Hr Saida]] -> 0.43402778 | N47: 153677 | O47: 153723 | P47: =Tabela32[[#This Row],[Km Chegada]]-Tabela32[[#This Row],[Km Saída]] -> 46 | Q47: 76 | R47: 11 | S47: 11 | T47: =Tabela32[[#This Row],[Entregas]]-Tabela32[[#This Row],[Realizadas]] -> 0 | U47: =Tabela32[[#This Row],[Realizadas]]/Tabela32[[#This Row],[Entregas]] -> 1 | V47: =IF(Tabela32[[#This Row],[% Entrega]]>=96%,"Atendeu a Meta","Não Atendeu a Meta") -> Atendeu a Meta | W47: Ananindeua | X47: 2 | Y47: 9 , 5
A48: 46244 | B48: =YEAR(Tabela32[[#This Row],[Data]]) -> 2026 | C48: =MONTH(Tabela32[[#This Row],[Data]]) -> 8 | D48: IUG8882 | E48: 4 | F48: =IFERROR(VLOOKUP(Tabela32[[#This Row],[Placa]],Planilha2!$A$1:$B$12,2,0),"") -> Wesley | G48: 6699.26 | H48: 152797.52 | I48: 1636 | J48: =IFERROR(Tabela32[[#This Row],[Valor Frete]]/Tabela32[[#This Row],[Valor Mercadoria]],"") -> 0.043844036 | K48: 0.29166667 | L48: 0.73611111 | M48: =Tabela32[[#This Row],[Hr Chegada]]-Tabela32[[#This Row],[Hr Saida]] -> 0.44444444 | N48: 302698 | O48: 302761 | P48: =Tabela32[[#This Row],[Km Chegada]]-Tabela32[[#This Row],[Km Saída]] -> 63 | Q48: 231 | R48: 21 | S48: 21 | T48: =Tabela32[[#This Row],[Entregas]]-Tabela32[[#This Row],[Realizadas]] -> 0 | U48: =Tabela32[[#This Row],[Realizadas]]/Tabela32[[#This Row],[Entregas]] -> 1 | V48: =IF(Tabela32[[#This Row],[% Entrega]]>=96%,"Atendeu a Meta","Não Atendeu a Meta") -> Atendeu a Meta | W48: Belém | X48: 0 | Y48: 0
A49: 46244 | B49: =YEAR(Tabela32[[#This Row],[Data]]) -> 2026 | C49: =MONTH(Tabela32[[#This Row],[Data]]) -> 8 | D49: TRD2G21 | E49: 3 | F49: =IFERROR(VLOOKUP(Tabela32[[#This Row],[Placa]],Planilha2!$A$1:$B$12,2,0),"") -> Arnaldo | G49: 10479.64 | H49: 203070.96 | I49: 2866 | J49: =IFERROR(Tabela32[[#This Row],[Valor Frete]]/Tabela32[[#This Row],[Valor Mercadoria]],"") -> 0.051605803 | K49: 0.29166667 | L49: 0.71736111 | M49: =Tabela32[[#This Row],[Hr Chegada]]-Tabela32[[#This Row],[Hr Saida]] -> 0.42569444 | N49: 11777 | O49: 11840 | P49: =Tabela32[[#This Row],[Km Chegada]]-Tabela32[[#This Row],[Km Saída]] -> 63 | Q49: 107 | R49: 20 | S49: 20 | T49: =Tabela32[[#This Row],[Entregas]]-Tabela32[[#This Row],[Realizadas]] -> 0 | U49: =Tabela32[[#This Row],[Realizadas]]/Tabela32[[#This Row],[Entregas]] -> 1 | V49: =IF(Tabela32[[#This Row],[% Entrega]]>=96%,"Atendeu a Meta","Não Atendeu a Meta") -> Atendeu a Meta | W49: Belém | X49: 0 | Y49: 0
A50: 46244 | B50: =YEAR(Tabela32[[#This Row],[Data]]) -> 2026 | C50: =MONTH(Tabela32[[#This Row],[Data]]) -> 8 | D50: IUG8767 | E50: 5 | F50: =IFERROR(VLOOKUP(Tabela32[[#This Row],[Placa]],Planilha2!$A$1:$B$12,2,0),"") -> Jerson | G50: 9608.5 | H50: 214881.65 | I50: 2970 | J50: =IFERROR(Tabela32[[#This Row],[Valor Frete]]/Tabela32[[#This Row],[Valor Mercadoria]],"") -> 0.044715312 | K50: 0.29166667 | L50: 0.81736111 | M50: =Tabela32[[#This Row],[Hr Chegada]]-Tabela32[[#This Row],[Hr Saida]] -> 0.52569444 | N50: 278977 | O50: 279059 | P50: =Tabela32[[#This Row],[Km Chegada]]-Tabela32[[#This Row],[Km Saída]] -> 82 | Q50: 491 | R50: 23 | S50: 23 | T50: =Tabela32[[#This Row],[Entregas]]-Tabela32[[#This Row],[Realizadas]] -> 0 | U50: =Tabela32[[#This Row],[Realizadas]]/Tabela32[[#This Row],[Entregas]] -> 1 | V50: =IF(Tabela32[[#This Row],[% Entrega]]>=96%,"Atendeu a Meta","Não Atendeu a Meta") -> Atendeu a Meta | W50: Belém | X50: 2 | Y50: 42, 9
A51: 46244 | B51: =YEAR(Tabela32[[#This Row],[Data]]) -> 2026 | C51: =MONTH(Tabela32[[#This Row],[Data]]) -> 8 | D51: LTY8B39 | E51: 11 | F51: =IFERROR(VLOOKUP(Tabela32[[#This Row],[Placa]],Planilha2!$A$1:$B$12,2,0),"") -> Gilberto | G51: 15692.95 | H51: 402526.01 | I51: 3125 | J51: =IFERROR(Tabela32[[#This Row],[Valor Frete]]/Tabela32[[#This Row],[Valor Mercadoria]],"") -> 0.038986176 | K51: 0.27083333 | L51: 0.71597222 | M51: =Tabela32[[#This Row],[Hr Chegada]]-Tabela32[[#This Row],[Hr Saida]] -> 0.44513889 | N51: 117363 | O51: 117491 | P51: =Tabela32[[#This Row],[Km Chegada]]-Tabela32[[#This Row],[Km Saída]] -> 128 | Q51: 40 | R51: 3 | S51: 3 | T51: =Tabela32[[#This Row],[Entregas]]-Tabela32[[#This Row],[Realizadas]] -> 0 | U51: =Tabela32[[#This Row],[Realizadas]]/Tabela32[[#This Row],[Entregas]] -> 1 | V51: =IF(Tabela32[[#This Row],[% Entrega]]>=96%,"Atendeu a Meta","Não Atendeu a Meta") -> Atendeu a Meta | W51: Castanhal | X51: 0 | Y51: 0
A52: 46244 | B52: =YEAR(Tabela32[[#This Row],[Data]]) -> 2026 | C52: =MONTH(Tabela32[[#This Row],[Data]]) -> 8 | D52: IXY4731 | E52: 1 | F52: =IFERROR(VLOOKUP(Tabela32[[#This Row],[Placa]],Planilha2!$A$1:$B$12,2,0),"") -> Osvaldo | G52: 1580.23 | H52: 24049.8 | I52: 440 | J52: =IFERROR(Tabela32[[#This Row],[Valor Frete]]/Tabela32[[#This Row],[Valor Mercadoria]],"") -> 0.065706576 | K52: 0.29166667 | L52: 0.76041667 | M52: =Tabela32[[#This Row],[Hr Chegada]]-Tabela32[[#This Row],[Hr Saida]] -> 0.46875 | N52: 140814 | O52: 140931 | P52: =Tabela32[[#This Row],[Km Chegada]]-Tabela32[[#This Row],[Km Saída]] -> 117 | Q52: 99 | R52: 7 | S52: 7 | T52: =Tabela32[[#This Row],[Entregas]]-Tabela32[[#This Row],[Realizadas]] -> 0 | U52: =Tabela32[[#This Row],[Realizadas]]/Tabela32[[#This Row],[Entregas]] -> 1 | V52: =IF(Tabela32[[#This Row],[% Entrega]]>=96%,"Atendeu a Meta","Não Atendeu a Meta") -> Atendeu a Meta | W52: Benevides | X52: 0 | Y52: 0
A53: 46244 | B53: =YEAR(Tabela32[[#This Row],[Data]]) -> 2026 | C53: =MONTH(Tabela32[[#This Row],[Data]]) -> 8 | D53: IUG8855 | E53: 1 | F53: =IFERROR(VLOOKUP(Tabela32[[#This Row],[Placa]],Planilha2!$A$1:$B$12,2,0),"") -> Rosinaldo | G53: 5577.17 | H53: 36607.75 | I53: 541 | J53: =IFERROR(Tabela32[[#This Row],[Valor Frete]]/Tabela32[[#This Row],[Valor Mercadoria]],"") -> 0.15234943 | K53: 0.29166667 | L53: 0.73611111 | M53: =Tabela32[[#This Row],[Hr Chegada]]-Tabela32[[#This Row],[Hr Saida]] -> 0.44444444 | N53: 289773 | O53: 289852 | P53: =Tabela32[[#This Row],[Km Chegada]]-Tabela32[[#This Row],[Km Saída]] -> 79 | Q53: 104 | R53: 9 | S53: 9 | T53: =Tabela32[[#This Row],[Entregas]]-Tabela32[[#This Row],[Realizadas]] -> 0 | U53: =Tabela32[[#This Row],[Realizadas]]/Tabela32[[#This Row],[Entregas]] -> 1 | V53: =IF(Tabela32[[#This Row],[% Entrega]]>=96%,"Atendeu a Meta","Não Atendeu a Meta") -> Atendeu a Meta | W53: Benevides | X53: 0 | Y53: 0
A54: 46244 | B54: =YEAR(Tabela32[[#This Row],[Data]]) -> 2026 | C54: =MONTH(Tabela32[[#This Row],[Data]]) -> 8 | D54: RKV1173 | E54: 1 | F54: =IFERROR(VLOOKUP(Tabela32[[#This Row],[Placa]],Planilha2!$A$1:$B$12,2,0),"") -> William | G54: 13472.32 | H54: 158606.97 | I54: 2718 | J54: =IFERROR(Tabela32[[#This Row],[Valor Frete]]/Tabela32[[#This Row],[Valor Mercadoria]],"") -> 0.084941538 | K54: 0.29166667 | L54: 0.76180556 | M54: =Tabela32[[#This Row],[Hr Chegada]]-Tabela32[[#This Row],[Hr Saida]] -> 0.47013889 | N54: 123458 | O54: 123539 | P54: =Tabela32[[#This Row],[Km Chegada]]-Tabela32[[#This Row],[Km Saída]] -> 81 | Q54: 238 | R54: 20 | S54: 20 | T54: =Tabela32[[#This Row],[Entregas]]-Tabela32[[#This Row],[Realizadas]] -> 0 | U54: =Tabela32[[#This Row],[Realizadas]]/Tabela32[[#This Row],[Entregas]] -> 1 | V54: =IF(Tabela32[[#This Row],[% Entrega]]>=96%,"Atendeu a Meta","Não Atendeu a Meta") -> Atendeu a Meta | W54: Ananindeua | X54: 0 | Y54: 0
A55: 46244 | B55: =YEAR(Tabela32[[#This Row],[Data]]) -> 2026 | C55: =MONTH(Tabela32[[#This Row],[Data]]) -> 8 | D55: IVX5G13 | E55: 1 | F55: =IFERROR(VLOOKUP(Tabela32[[#This Row],[Placa]],Planilha2!$A$1:$B$12,2,0),"") -> Heremilton | G55: 23271.12 | H55: 849954.78 | I55: 4993 | J55: =IFERROR(Tabela32[[#This Row],[Valor Frete]]/Tabela32[[#This Row],[Valor Mercadoria]],"") -> 0.027379245 | K55: 0.29166667 | L55: 0.74305556 | M55: =Tabela32[[#This Row],[Hr Chegada]]-Tabela32[[#This Row],[Hr Saida]] -> 0.45138889 | N55: 364007 | O55: 364027 | P55: =Tabela32[[#This Row],[Km Chegada]]-Tabela32[[#This Row],[Km Saída]] -> 20 | Q55: 604 | R55: 39 | S55: 39 | T55: =Tabela32[[#This Row],[Entregas]]-Tabela32[[#This Row],[Realizadas]] -> 0 | U55: =Tabela32[[#This Row],[Realizadas]]/Tabela32[[#This Row],[Entregas]] -> 1 | V55: =IF(Tabela32[[#This Row],[% Entrega]]>=96%,"Atendeu a Meta","Não Atendeu a Meta") -> Atendeu a Meta | W55: Belém | X55: 0 | Y55: 0
A56: 46245 | B56: =YEAR(Tabela32[[#This Row],[Data]]) -> 2026 | C56: =MONTH(Tabela32[[#This Row],[Data]]) -> 8 | D56: TRD2G21 | E56: 3 | F56: =IFERROR(VLOOKUP(Tabela32[[#This Row],[Placa]],Planilha2!$A$1:$B$12,2,0),"") -> Arnaldo | G56: 8333.45 | H56: 173187.04 | I56: 1310 | J56: =IFERROR(Tabela32[[#This Row],[Valor Frete]]/Tabela32[[#This Row],[Valor Mercadoria]],"") -> 0.048118208 | K56: 0.29166667 | L56: 0.73611111 | M56: =Tabela32[[#This Row],[Hr Chegada]]-Tabela32[[#This Row],[Hr Saida]] -> 0.44444444 | N56: 11841 | O56: 11896 | P56: =Tabela32[[#This Row],[Km Chegada]]-Tabela32[[#This Row],[Km Saída]] -> 55 | Q56: 205 | R56: 28 | S56: 28 | T56: =Tabela32[[#This Row],[Entregas]]-Tabela32[[#This Row],[Realizadas]] -> 0 | U56: =Tabela32[[#This Row],[Realizadas]]/Tabela32[[#This Row],[Entregas]] -> 1 | V56: =IF(Tabela32[[#This Row],[% Entrega]]>=96%,"Atendeu a Meta","Não Atendeu a Meta") -> Atendeu a Meta | W56: Belém | X56: 0 | Y56: 0
A57: 46245 | B57: =YEAR(Tabela32[[#This Row],[Data]]) -> 2026 | C57: =MONTH(Tabela32[[#This Row],[Data]]) -> 8 | D57: IUG8855 | E57: 1 | F57: =IFERROR(VLOOKUP(Tabela32[[#This Row],[Placa]],Planilha2!$A$1:$B$12,2,0),"") -> Rosinaldo | G57: 4968.05 | H57: 99510.63 | I57: 664 | J57: =IFERROR(Tabela32[[#This Row],[Valor Frete]]/Tabela32[[#This Row],[Valor Mercadoria]],"") -> 0.049924817 | K57: 0.29166667 | L57: 0.75 | M57: =Tabela32[[#This Row],[Hr Chegada]]-Tabela32[[#This Row],[Hr Saida]] -> 0.45833333 | N57: 289832 | O57: 289919 | P57: =Tabela32[[#This Row],[Km Chegada]]-Tabela32[[#This Row],[Km Saída]] -> 87 | Q57: 202 | R57: 10 | S57: 10 | T57: =Tabela32[[#This Row],[Entregas]]-Tabela32[[#This Row],[Realizadas]] -> 0 | U57: =Tabela32[[#This Row],[Realizadas]]/Tabela32[[#This Row],[Entregas]] -> 1 | V57: =IF(Tabela32[[#This Row],[% Entrega]]>=96%,"Atendeu a Meta","Não Atendeu a Meta") -> Atendeu a Meta | W57: Belém | X57: 0 | Y57: 0
A58: 46245 | B58: =YEAR(Tabela32[[#This Row],[Data]]) -> 2026 | C58: =MONTH(Tabela32[[#This Row],[Data]]) -> 8 | D58: IUG8882 | E58: 2 | F58: =IFERROR(VLOOKUP(Tabela32[[#This Row],[Placa]],Planilha2!$A$1:$B$12,2,0),"") -> Wesley | G58: 5884.88 | H58: 103112.02 | I58: 1764 | J58: =IFERROR(Tabela32[[#This Row],[Valor Frete]]/Tabela32[[#This Row],[Valor Mercadoria]],"") -> 0.057072687 | K58: 0.29166667 | L58: 0.75694444 | M58: =Tabela32[[#This Row],[Hr Chegada]]-Tabela32[[#This Row],[Hr Saida]] -> 0.46527778 | N58: 302761 | O58: 302814 | P58: =Tabela32[[#This Row],[Km Chegada]]-Tabela32[[#This Row],[Km Saída]] -> 53 | Q58: 408 | R58: 22 | S58: 22 | T58: =Tabela32[[#This Row],[Entregas]]-Tabela32[[#This Row],[Realizadas]] -> 0 | U58: =Tabela32[[#This Row],[Realizadas]]/Tabela32[[#This Row],[Entregas]] -> 1 | V58: =IF(Tabela32[[#This Row],[% Entrega]]>=96%,"Atendeu a Meta","Não Atendeu a Meta") -> Atendeu a Meta | W58: Belém | X58: 0 | Y58: 0
A59: 46245 | B59: =YEAR(Tabela32[[#This Row],[Data]]) -> 2026 | C59: =MONTH(Tabela32[[#This Row],[Data]]) -> 8 | D59: IXY4731 | E59: 1 | F59: =IFERROR(VLOOKUP(Tabela32[[#This Row],[Placa]],Planilha2!$A$1:$B$12,2,0),"") -> Osvaldo | G59: 7511.12 | H59: 66056.6 | I59: 1345 | J59: =IFERROR(Tabela32[[#This Row],[Valor Frete]]/Tabela32[[#This Row],[Valor Mercadoria]],"") -> 0.11370734 | K59: 0.29166667 | L59: 0.75 | M59: =Tabela32[[#This Row],[Hr Chegada]]-Tabela32[[#This Row],[Hr Saida]] -> 0.45833333 | N59: 140931 | O59: 141128 | P59: =Tabela32[[#This Row],[Km Chegada]]-Tabela32[[#This Row],[Km Saída]] -> 197 | Q59: 176 | R59: 17 | S59: 17 | T59: =Tabela32[[#This Row],[Entregas]]-Tabela32[[#This Row],[Realizadas]] -> 0 | U59: =Tabela32[[#This Row],[Realizadas]]/Tabela32[[#This Row],[Entregas]] -> 1 | V59: =IF(Tabela32[[#This Row],[% Entrega]]>=96%,"Atendeu a Meta","Não Atendeu a Meta") -> Atendeu a Meta | W59: Benevides | X59: 0 | Y59: 0
A60: 46245 | B60: =YEAR(Tabela32[[#This Row],[Data]]) -> 2026 | C60: =MONTH(Tabela32[[#This Row],[Data]]) -> 8 | D60: IYD7460 | E60: 1 | F60: =IFERROR(VLOOKUP(Tabela32[[#This Row],[Placa]],Planilha2!$A$1:$B$12,2,0),"") -> Paulo | G60: 1584.91 | H60: 7487.8 | I60: 195 | J60: =IFERROR(Tabela32[[#This Row],[Valor Frete]]/Tabela32[[#This Row],[Valor Mercadoria]],"") -> 0.21166564 | K60: 0.29166667 | L60: 0.66666667 | M60: =Tabela32[[#This Row],[Hr Chegada]]-Tabela32[[#This Row],[Hr Saida]] -> 0.375 | N60: 153694 | O60: 153753 | P60: =Tabela32[[#This Row],[Km Chegada]]-Tabela32[[#This Row],[Km Saída]] -> 59 | Q60: 31 | R60: 1 | S60: 1 | T60: =Tabela32[[#This Row],[Entregas]]-Tabela32[[#This Row],[Realizadas]] -> 0 | U60: =Tabela32[[#This Row],[Realizadas]]/Tabela32[[#This Row],[Entregas]] -> 1 | V60: =IF(Tabela32[[#This Row],[% Entrega]]>=96%,"Atendeu a Meta","Não Atendeu a Meta") -> Atendeu a Meta | W60: Benevides | X60: 0 | Y60: 0
A61: 46245 | B61: =YEAR(Tabela32[[#This Row],[Data]]) -> 2026 | C61: =MONTH(Tabela32[[#This Row],[Data]]) -> 8 | D61: IUG8767 | E61: 5 | F61: =IFERROR(VLOOKUP(Tabela32[[#This Row],[Placa]],Planilha2!$A$1:$B$12,2,0),"") -> Jerson | G61: 6261.94 | H61: 11079.14 | I61: 1182 | J61: =IFERROR(Tabela32[[#This Row],[Valor Frete]]/Tabela32[[#This Row],[Valor Mercadoria]],"") -> 0.56520091 | K61: 0.29166667 | L61: 0.74652778 | M61: =Tabela32[[#This Row],[Hr Chegada]]-Tabela32[[#This Row],[Hr Saida]] -> 0.45486111 | N61: 279059 | O61: 279145 | P61: =Tabela32[[#This Row],[Km Chegada]]-Tabela32[[#This Row],[Km Saída]] -> 86 | Q61: 190 | R61: 30 | S61: 30 | T61: =Tabela32[[#This Row],[Entregas]]-Tabela32[[#This Row],[Realizadas]] -> 0 | U61: =Tabela32[[#This Row],[Realizadas]]/Tabela32[[#This Row],[Entregas]] -> 1 | V61: =IF(Tabela32[[#This Row],[% Entrega]]>=96%,"Atendeu a Meta","Não Atendeu a Meta") -> Atendeu a Meta | W61: Belém | X61: 0 | Y61: 0
A62: 46245 | B62: =YEAR(Tabela32[[#This Row],[Data]]) -> 2026 | C62: =MONTH(Tabela32[[#This Row],[Data]]) -> 8 | D62: RKV1173 | E62: 4 | F62: =IFERROR(VLOOKUP(Tabela32[[#This Row],[Placa]],Planilha2!$A$1:$B$12,2,0),"") -> William | G62: 13239.31 | H62: 288957.73 | I62: 2473 | J62: =IFERROR(Tabela32[[#This Row],[Valor Frete]]/Tabela32[[#This Row],[Valor Mercadoria]],"") -> 0.045817463 | K62: 0.29166667 | L62: 0.75069444 | M62: =Tabela32[[#This Row],[Hr Chegada]]-Tabela32[[#This Row],[Hr Saida]] -> 0.45902778 | N62: 123554 | O62: 123596 | P62: =Tabela32[[#This Row],[Km Chegada]]-Tabela32[[#This Row],[Km Saída]] -> 42 | Q62: 364 | R62: 41 | S62: 38 | T62: =Tabela32[[#This Row],[Entregas]]-Tabela32[[#This Row],[Realizadas]] -> 3 | U62: =Tabela32[[#This Row],[Realizadas]]/Tabela32[[#This Row],[Entregas]] -> 0.92682927 | V62: =IF(Tabela32[[#This Row],[% Entrega]]>=96%,"Atendeu a Meta","Não Atendeu a Meta") -> Não Atendeu a Meta | W62: Belém | X62: 3 | Y62: 13,13,13
A63: 46245 | B63: =YEAR(Tabela32[[#This Row],[Data]]) -> 2026 | C63: =MONTH(Tabela32[[#This Row],[Data]]) -> 8 | D63: LTY8B39 | E63: 11 | F63: =IFERROR(VLOOKUP(Tabela32[[#This Row],[Placa]],Planilha2!$A$1:$B$12,2,0),"") -> Gilberto | G63: 9594.73 | H63: 136318.66 | I63: 1306 | J63: =IFERROR(Tabela32[[#This Row],[Valor Frete]]/Tabela32[[#This Row],[Valor Mercadoria]],"") -> 0.070384568 | K63: 0.25 | L63: 0.74375 | M63: =Tabela32[[#This Row],[Hr Chegada]]-Tabela32[[#This Row],[Hr Saida]] -> 0.49375 | N63: 117491 | O63: 117629 | P63: =Tabela32[[#This Row],[Km Chegada]]-Tabela32[[#This Row],[Km Saída]] -> 138 | Q63: 202 | R63: 37 | S63: 37 | T63: =Tabela32[[#This Row],[Entregas]]-Tabela32[[#This Row],[Realizadas]] -> 0 | U63: =Tabela32[[#This Row],[Realizadas]]/Tabela32[[#This Row],[Entregas]] -> 1 | V63: =IF(Tabela32[[#This Row],[% Entrega]]>=96%,"Atendeu a Meta","Não Atendeu a Meta") -> Atendeu a Meta | W63: Castanhal | X63: 1 | Y63: 8
...
